<?xml version="1.0" ?>
<!-- =================================================================================== -->
<!-- |    This document was autogenerated by xacro from queenie.xacro                  | -->
<!-- |    EDITING THIS FILE BY HAND IS NOT RECOMMENDED                                 | -->
<!-- =================================================================================== -->
<robot name="queenie">
  <gazebo reference="right_finger">
    <mu1>1500</mu1>
    <mu2>100</mu2>
    <kp>1e5</kp>
    <kd>100.0</kd>
    <maxDepth>0</maxDepth>
    <!-- <minDepth>0.001</minDepth> -->
    <!-- <maxVel>1.0</maxVel> -->
    <selfCollide>false</selfCollide>
  </gazebo>
  <gazebo reference="left_finger">
    <mu1>1500.0</mu1>
    <mu2>100.0</mu2>
    <kp>1e5</kp>
    <kd>100.0</kd>
    <!-- <minDepth>0.001</minDepth> -->
    <!-- <maxVel>1.0</maxVel> -->
    <selfCollide>false</selfCollide>
  </gazebo>
  <gazebo reference="gripper_pole">
    <material>Gazebo/Green</material>
    <selfCollide>false</selfCollide>
  </gazebo>
  <gazebo reference="gripper_pole_vertical">
    <material>Gazebo/Blue</material>
    <selfCollide>false</selfCollide>
  </gazebo>
  <gazebo reference="left_wheel">
    <material>Gazebo/Green</material>
    <mu1>1500.0</mu1>
    <mu2>100.0</mu2>
    <kp>1e15</kp>
    <kd>1e10</kd>
    <minDepth>0.00</minDepth>
    <maxVel>0</maxVel>
  </gazebo>
  <gazebo reference="right_wheel">
    <material>Gazebo/Green</material>
    <mu1>1500.0</mu1>
    <mu2>100.0</mu2>
    <kp>1e15</kp>
    <kd>1e10</kd>
    <minDepth>0.00</minDepth>
    <maxVel>0</maxVel>
  </gazebo>
  <gazebo reference="left_wheel_back">
    <material>Gazebo/Green</material>
    <mu1>1500.0</mu1>
    <mu2>100.0</mu2>
    <kp>1e15</kp>
    <kd>1e10</kd>
    <minDepth>0.00</minDepth>
    <maxVel>0</maxVel>
  </gazebo>
  <gazebo reference="right_wheel_back">
    <material>Gazebo/Green</material>
    <mu1>1500.0</mu1>
    <mu2>100.0</mu2>
    <kp>1e15</kp>
    <kd>1e10</kd>
    <minDepth>0.00</minDepth>
    <maxVel>0</maxVel>
  </gazebo>
  <gazebo reference="camera">
    <material>Gazebo/Red</material>
  </gazebo>
  <gazebo reference="chassis">
    <material>Gazebo/Blue</material>
    <mu1>0.00001</mu1>
    <mu2>0.00001</mu2>
    <kp>1000000.0</kp>
    <kd>100.0</kd>
    <!-- <minDepth>0.001</minDepth> -->
    <maxVel>0</maxVel>
  </gazebo>
  <gazebo reference="front_caster">
    <material>Gazebo/Red</material>
    <mu1>0.0001</mu1>
    <mu2>0.0001</mu2>
    <kp>1e15</kp>
    <kd>1e13</kd>
    <!-- <minDepth>0.001</minDepth> -->
    <maxVel>0</maxVel>
  </gazebo>
  <gazebo reference="back_caster">
    <material>Gazebo/Red</material>
    <mu1>0.0001</mu1>
    <mu2>0.0001</mu2>
    <kp>1e15</kp>
    <kd>1e13</kd>
    <maxVel>0</maxVel>
  </gazebo>
  <gazebo reference="palm">
    <material>Gazebo/Red</material>
    <mu1>1500.0</mu1>
    <mu2>100.0</mu2>
    <kp>1000000.0</kp>
    <kd>100.0</kd>
    <!-- <minDepth>0.001</minDepth> -->
    <maxVel>1.0</maxVel>
    <selfCollide>false</selfCollide>
  </gazebo>
  <!-- <gazebo reference="palm_riser">
    <provideFeedback>true</provideFeedback>
  </gazebo>
  <gazebo>
    <plugin name="ft_sensor" filename="libgazebo_ros_ft_sensor.so">
      <updateRate>100</updateRate>
      <topicName>ft_sensor_topic</topicName>
      <jointName>palm_riser</jointName>
    </plugin>
   </gazebo> -->
  <gazebo reference="head">
    <material>Gazebo/Red</material>
    <mu1>0</mu1>
    <mu2>0.0001</mu2>
    <kp>1e15</kp>
    <kd>1e13</kd>
    <maxVel>0</maxVel>
    <selfCollide>false</selfCollide>
  </gazebo>
  <!-- <gazebo>
    <plugin name="differential_drive_controller" filename="libgazebo_ros_diff_drive.so">
      <legacyMode>false</legacyMode>
      <alwaysOn>true</alwaysOn>
      <updateRate>100</updateRate>
      <leftJoint>left_wheel_hinge</leftJoint>
      <rightJoint>right_wheel_hinge</rightJoint>
      <wheelSeparation>0.4</wheelSeparation>
      <wheelDiameter>0.2</wheelDiameter>
      <torque>100</torque>
      <commandTopic>cmd_vel</commandTopic>
      <odometryTopic>odom</odometryTopic>
      <odometryFrame>odom</odometryFrame>
      <robotBaseFrame>robot_footprint</robotBaseFrame>
      <publishWheelTF>false</publishWheelTF>
      <publishWheelJointState>false</publishWheelJointState>
      <rosDebugLevel>na</rosDebugLevel>
      <wheelAcceleration>0</wheelAcceleration>
      <wheelTorque>50</wheelTorque>
      <odometrySource>world</odometrySource>
      <publishTf>1</publishTf>
      <publishOdomTF>true</publishOdomTF>
    </plugin>
  </gazebo> -->
  <gazebo>
    <plugin filename="libgazebo_ros_skid_steer_drive.so" name="skid_steer_drive_controller">
      <updateRate>100.0</updateRate>
      <!-- <robotNamespace>/</robotNamespace> -->
      <leftFrontJoint>left_wheel_hinge</leftFrontJoint>
      <rightFrontJoint>right_wheel_hinge</rightFrontJoint>
      <leftRearJoint>left_wheel_back_hinge</leftRearJoint>
      <rightRearJoint>right_wheel_back_hinge</rightRearJoint>
      <wheelSeparation>0.6</wheelSeparation>
      <wheelDiameter>0.2</wheelDiameter>
      <robotBaseFrame>robot_footprint</robotBaseFrame>
      <torque>50</torque>
      <topicName>cmd_vel</topicName>
      <broadcastTF>true</broadcastTF>
      <publishTf>1</publishTf>
      <publishOdomTF>true</publishOdomTF>
      <covariance_x>0</covariance_x>
      <covariance_y>0</covariance_y>
      <covariance_yaw>0</covariance_yaw>
    </plugin>
  </gazebo>
  <!-- camera -->
  <!-- <gazebo reference="camera">
    <sensor type="camera" name="camera1">
      <update_rate>30.0</update_rate>
      <camera name="head">
        <horizontal_fov>1.3962634</horizontal_fov>
        <image>
          <width>800</width>
          <height>800</height>
          <format>R8G8B8</format>
        </image>
        <clip>
          <near>0.02</near>
          <far>300</far>
        </clip>
      </camera>
      <plugin name="camera_controller" filename="libgazebo_ros_camera.so">
        <alwaysOn>true</alwaysOn>
        <updateRate>0.0</updateRate>
        <cameraName>camera</cameraName>
        <imageTopicName>rgb/image_raw</imageTopicName>
        <cameraInfoTopicName>rgb/camera_info</cameraInfoTopicName>
        <frameName>camera</frameName>
        <hackBaseline>0.07</hackBaseline>
        <distortionK1>0.0</distortionK1>
        <distortionK2>0.0</distortionK2>
        <distortionK3>0.0</distortionK3>
        <distortionT1>0.0</distortionT1>
        <distortionT2>0.0</distortionT2>
      </plugin>


    </sensor>
  </gazebo> -->
  <gazebo reference="palm">
    <sensor name="gripper_contact_sensor" type="contact">
      <always_on>true</always_on>
      <update_rate>10</update_rate>
      <contact>
        <collision>head_x_fixed_joint_lump__palm_collision_collision</collision>
      </contact>
      <plugin filename="libgazebo_ros_bumper.so" name="palm_bumper">
        <bumperTopicName>palm_contact_states</bumperTopicName>
        <frameName>odom</frameName>
      </plugin>
    </sensor>
  </gazebo>
  <gazebo reference="left_finger">
    <sensor name="gripper_contact_sensor" type="contact">
      <always_on>true</always_on>
      <update_rate>10</update_rate>
      <contact>
        <collision>left_finger_collision_collision</collision>
      </contact>
      <plugin filename="libgazebo_ros_bumper.so" name="left_finger_bumper">
        <bumperTopicName>left_finger_contact_states</bumperTopicName>
        <frameName>odom</frameName>
      </plugin>
    </sensor>
  </gazebo>
  <gazebo reference="right_finger">
    <sensor name="gripper_contact_sensor" type="contact">
      <always_on>true</always_on>
      <update_rate>10</update_rate>
      <contact>
        <collision>right_finger_collision_collision</collision>
      </contact>
      <plugin filename="libgazebo_ros_bumper.so" name="right_finger_bumper">
        <bumperTopicName>right_finger_contact_states</bumperTopicName>
        <frameName>odom</frameName>
      </plugin>
    </sensor>
  </gazebo>
  <gazebo reference="camera">
    <sensor name="camera" type="depth">
      <visualize>false</visualize>
      <update_rate>10.0</update_rate>
      <camera name="head">
        <horizontal_fov>1.3962634</horizontal_fov>
        <image>
          <width>84</width>
          <height>84</height>
          <format>R8G8B8</format>
        </image>
        <clip>
          <near>0.01</near>
          <!-- <far>100</far> -->
        </clip>
      </camera>
      <plugin filename="libgazebo_ros_openni_kinect.so" name="camera_plugin">
        <baseline>0.01</baseline>
        <alwaysOn>true</alwaysOn>
        <!-- Keep this zero, update_rate in the parent <sensor> tag
            will control the frame rate. -->
        <updateRate>0</updateRate>
        <cameraName>camera_ir</cameraName>
        <imageTopicName>/camera/color/image_raw</imageTopicName>
        <cameraInfoTopicName>/camera/color/camera_info</cameraInfoTopicName>
        <depthImageTopicName>/camera/depth/image_raw</depthImageTopicName>
        <depthImageCameraInfoTopicName>/camera/depth/camera_info</depthImageCameraInfoTopicName>
        <pointCloudTopicName>/camera/depth/points</pointCloudTopicName>
        <frameName>camera_optical</frameName>
        <pointCloudCutoff>0.01</pointCloudCutoff>
        <pointCloudCutoffMax>10</pointCloudCutoffMax>
        <distortionK1>0</distortionK1>
        <distortionK2>0</distortionK2>
        <distortionK3>0</distortionK3>
        <distortionT1>0</distortionT1>
        <distortionT2>0</distortionT2>
        <CxPrime>0</CxPrime>
        <Cx>0</Cx>
        <Cy>0</Cy>
        <focalLength>0</focalLength>
        <hackBaseline>0</hackBaseline>
      </plugin>
    </sensor>
  </gazebo>
  <!-- <gazebo>
   <plugin name="gazebo_grasp_fix" filename="libgazebo_grasp_fix.so">
        <arm>
           <arm_name>name-of-arm</arm_name>
           <palm_link> palm  </palm_link>
           <gripper_link> left_finger </gripper_link>
           <gripper_link> right_finger </gripper_link>
        </arm>
       <forces_angle_tolerance>90</forces_angle_tolerance>
       <update_rate>4</update_rate>
       <grip_count_threshold>4</grip_count_threshold>
       <max_grip_count>8</max_grip_count>
       <release_tolerance>0.005</release_tolerance>
       <disable_collisions_on_attach>false</disable_collisions_on_attach>
       <contact_topic>__default_topic__</contact_topic>
    </plugin>
</gazebo> -->
  <gazebo>
    <plugin filename="libgazebo_ros_control.so" name="gazebo_ros_control">
      <robotNamespace>/queenie</robotNamespace>
    </plugin>
  </gazebo>
  <!-- <xacro:macro name="gripper_trans" params="prefix">
        <transmission name="${prefix}_gripper_trans" type="SimpleTransmission">
            <type>transmission_interface/SimpleTransmission</type>
            <actuator name="${prefix}_gripper_motor">
                <mechanicalReduction>1</mechanicalReduction>
            </actuator>
            <joint name="${prefix}_gripper_joint">
                <hardwareInterface>hardware_interface/PositionJointInterface</hardwareInterface>
            </joint>
        </transmission>
    </xacro:macro>
    <xacro:gripper_trans prefix="left"/>
    <xacro:gripper_trans prefix="right"/> -->
  <!-- <transmission name="gripper_extension_trans" type="SimpleTransmission">
    <type>transmission_interface/SimpleTransmission</type>
    <actuator name="gripper_extension_motor">
      <mechanicalReduction>1</mechanicalReduction>
    </actuator>
    <joint name="gripper_extension">
      <hardwareInterface>hardware_interface/EffortJointInterface</hardwareInterface>
    </joint>
  </transmission> -->
  <transmission name="neck_trans" type="SimpleTransmission">
    <type>transmission_interface/SimpleTransmission</type>
    <actuator name="neck_trans">
      <mechanicalReduction>1</mechanicalReduction>
    </actuator>
    <joint name="neck">
      <hardwareInterface>hardware_interface/EffortJointInterface</hardwareInterface>
    </joint>
  </transmission>
  <transmission name="neck_x_trans" type="SimpleTransmission">
    <type>transmission_interface/SimpleTransmission</type>
    <actuator name="neck_x_trans">
      <mechanicalReduction>1</mechanicalReduction>
    </actuator>
    <joint name="neck_x">
      <hardwareInterface>hardware_interface/EffortJointInterface</hardwareInterface>
    </joint>
  </transmission>
  <!-- <transmission name="palm_riser_trans" type="SimpleTransmission">
    <type>transmission_interface/SimpleTransmission</type>
    <actuator name="palm_riser_motor">
      <mechanicalReduction>1</mechanicalReduction>
    </actuator>
    <joint name="palm_riser">
      <hardwareInterface>hardware_interface/EffortJointInterface</hardwareInterface>
    </joint>
  </transmission> -->
  <transmission name="palm_left_finger_trans" type="SimpleTransmission">
    <type>transmission_interface/SimpleTransmission</type>
    <actuator name="palm_left_finger_trans">
      <mechanicalReduction>1</mechanicalReduction>
    </actuator>
    <joint name="palm_left_finger">
      <hardwareInterface>hardware_interface/EffortJointInterface</hardwareInterface>
    </joint>
  </transmission>
  <!-- <transmission name="left_finger_to_tip_trans" type="SimpleTransmission">
    <type>transmission_interface/SimpleTransmission</type>
    <actuator name="left_finger_to_tip_trans">
      <mechanicalReduction>1</mechanicalReduction>
    </actuator>
    <joint name="left_finger_to_tip">
      <hardwareInterface>hardware_interface/EffortJointInterface</hardwareInterface>
    </joint>
  </transmission> -->
  <transmission name="palm_right_finger_trans" type="SimpleTransmission">
    <type>transmission_interface/SimpleTransmission</type>
    <actuator name="palm_right_finger_trans">
      <mechanicalReduction>1</mechanicalReduction>
    </actuator>
    <joint name="palm_right_finger">
      <hardwareInterface>hardware_interface/EffortJointInterface</hardwareInterface>
    </joint>
  </transmission>
  <!-- <transmission name="right_finger_to_tip_trans" type="SimpleTransmission">
    <type>transmission_interface/SimpleTransmission</type>
    <actuator name="right_finger_to_tip_trans">
      <mechanicalReduction>1</mechanicalReduction>
    </actuator>
    <joint name="right_finger_to_tip">
      <hardwareInterface>hardware_interface/EffortJointInterface</hardwareInterface>
    </joint>
  </transmission> -->
  <!-- <transmission name="gripper_extension_vertical_trans" type="SimpleTransmission">
    <type>transmission_interface/SimpleTransmission</type>
    <actuator name="gripper_extension_vertical_motor">
      <mechanicalReduction>1</mechanicalReduction>
    </actuator>
    <joint name="gripper_extension_vertical">
      <hardwareInterface>hardware_interface/PositionJointInterface</hardwareInterface>
    </joint>
  </transmission>

  <transmission name="gpv_to_lgv_trans" type="SimpleTransmission">
    <type>transmission_interface/SimpleTransmission</type>
    <actuator name="gpv_to_lgv_trans">
      <mechanicalReduction>1</mechanicalReduction>
    </actuator>
    <joint name="gpv_to_lgv">
      <hardwareInterface>hardware_interface/PositionJointInterface</hardwareInterface>
    </joint>
  </transmission>

  <transmission name="gpv_to_rgv_trans" type="SimpleTransmission">
    <type>transmission_interface/SimpleTransmission</type>
    <actuator name="gpv_to_rgv_trans">
      <mechanicalReduction>1</mechanicalReduction>
    </actuator>
    <joint name="gpv_to_rgv">
      <hardwareInterface>hardware_interface/PositionJointInterface</hardwareInterface>
    </joint>
  </transmission> -->
  <!-- <xacro:include filename="$(find queenie)/urdf/queenie.trans"  /> -->
  <link name="robot_footprint"/>
  <joint name="robot_footprint_joint" type="fixed">
    <origin rpy="0 0 0" xyz="0 0 0"/>
    <parent link="robot_footprint"/>
    <child link="chassis"/>
  </joint>
  <link name="chassis">
    <inertial>
      <origin rpy="0 0 0" xyz="0 0 0.05"/>
      <mass value="15"/>
      <inertia ixx="0.284375" ixy="0.0" ixz="0.0" iyy="0.284375" iyz="0.0" izz="0.46875"/>
    </inertial>
    <collision name="collision">
      <origin rpy=" 0 0 0" xyz="0 0 0.05"/>
      <geometry>
        <cylinder length="0.2" radius="0.25"/>
      </geometry>
    </collision>
    <visual name="chassis_visual">
      <origin rpy=" 0 0 0" xyz="0 0 0.05"/>
      <geometry>
        <cylinder length="0.2" radius="0.25"/>
      </geometry>
    </visual>
  </link>
  <!-- <joint name="chassis_front_caster" type="fixed">
    <parent link="chassis"/>
    <child link="front_caster"/>
    <origin xyz="0.15 0 -0.05" rpy="0 0 0"/>
  </joint>

  <link name="front_caster">
  <xacro:default_inertial_solid_sphere mass="0.1" radius="0.0499"/>
    <collision>
      <origin xyz="0 0 0" rpy=" 0 0 0"/>
      <geometry>
        <sphere radius="0.0499"/>
      </geometry>
    </collision>
    <visual>
      <origin xyz="0 0 0" rpy=" 0 0 0"/>
      <geometry>
        <sphere radius="0.05"/>
      </geometry>
    </visual>
  </link>

  <joint name="chassis_back_caster" type="fixed">
    <parent link="chassis"/>
    <child link="back_caster"/>
    <origin xyz="-0.15 0 -0.05" rpy="0 0 0"/>
  </joint>
  
  <link name="back_caster">
  <xacro:default_inertial_solid_sphere mass="0.1" radius="0.0499"/>
    <collision>
      <origin xyz="0 0 0" rpy=" 0 0 0"/>
      <geometry>
        <sphere radius="0.0499"/>
      </geometry>
    </collision>
    <visual>
      <origin xyz="0 0 0" rpy=" 0 0 0"/>
      <geometry>
        <sphere radius="0.05"/>
      </geometry>
    </visual>
  </link> -->
  <joint name="gripper_extension" type="fixed">
    <parent link="chassis"/>
    <child link="gripper_pole"/>
    <!-- <limit effort="1000.0" lower="-0.13" upper="0" velocity="0.05"/> -->
    <origin rpy="0 0 0" xyz="0.30 0 0.05"/>
  </joint>
  <link name="gripper_pole">
    <visual>
      <geometry>
        <box size="0.1 0.05 0.05"/>
      </geometry>
      <origin rpy="0 0 0 " xyz="0 0 0"/>
    </visual>
    <collision>
      <geometry>
        <box size="0.01 0.05 0.05"/>
      </geometry>
      <origin rpy="0 0 0 " xyz="0 0 0"/>
    </collision>
    <inertial>
      <!-- <xacro:insert_block name="origin"/> -->
      <origin rpy="0 0 0" xyz="0 0 0"/>
      <mass value="0.5"/>
      <inertia ixx="0.00020833333333333337" ixy="0.0" ixz="0.0" iyy="0.00020833333333333337" iyz="0.0" izz="0.00020833333333333337"/>
    </inertial>
  </link>
  <joint name="neck" type="revolute">
    <parent link="gripper_pole"/>
    <child link="head"/>
    <limit effort="1000.0" lower="-1.0471975511965976" upper="0.22" velocity="0.05"/>
    <origin rpy="0 0 0" xyz="0.0 0 0"/>
    <axis xyz="0 1 0"/>
    <dynamics damping="0.1" friction="0.1"/>
  </joint>
  <link name="head">
    <inertial>
      <!-- <xacro:insert_block name="origin"/> -->
      <origin rpy="0 0 0" xyz="0.0 0 0"/>
      <mass value="0.8"/>
      <inertia ixx="4.333333333333334e-05" ixy="0.0" ixz="0.0" iyy="8.333333333333334e-06" iyz="0.0" izz="4.833333333333335e-05"/>
    </inertial>
    <!-- <visual><geometry><sphere radius=".01"/></geometry></visual> -->
  </link>
  <joint name="neck_x" type="revolute">
    <parent link="head"/>
    <child link="head_x"/>
    <limit effort="1000.0" lower="-0.5" upper="0.5" velocity="0.05"/>
    <origin rpy="0 0 0" xyz="0.0 0 0"/>
    <axis xyz="1 0 0"/>
    <dynamics damping="0.1" friction="0.1"/>
  </joint>
  <link name="head_x">
    <inertial>
      <!-- <xacro:insert_block name="origin"/> -->
      <origin rpy="0 0 0" xyz="0.0 0 0"/>
      <mass value="0.8"/>
      <inertia ixx="4.333333333333334e-05" ixy="0.0" ixz="0.0" iyy="8.333333333333334e-06" iyz="0.0" izz="4.833333333333335e-05"/>
    </inertial>
    <!-- <visual><geometry><sphere radius=".01"/></geometry></visual> -->
  </link>
  <joint name="head_gripper_pole_vertical" type="fixed">
    <parent link="head_x"/>
    <child link="palm"/>
    <!-- <limit effort="1000.0" lower="-0.13" upper="0" velocity="0.5"/> -->
    <origin rpy="0 0 0" xyz="0.05 0 0"/>
  </joint>
  <!-- <link name="gripper_pole_vertical">
    <visual>
      <geometry>
        <box size="0.05 0.05 0.2"/>
      </geometry>
      <origin rpy="0 0 0 " xyz="0 0 0.075"/>
    </visual>
    <collision>
      <geometry>
        <box size="0.05 0.05 0.2"/>
      </geometry>
      <origin rpy="0 0 0 " xyz="0 0 0.075"/>
    </collision>
    <xacro:default_inertial_cuboid mass="0.3" x_length="0.05" y_length="0.05" z_length="0.2" x="0" y="0" z="0.075" r="0" p="0" yaw="0"/>
  </link> -->
  <!-- <joint name="palm_riser" type="prismatic">
    <parent link="gripper_pole_vertical"/>
    <child link="palm"/>
    <limit effort="1000.0" lower="0" upper="0.17" velocity="0.05"/>
    <origin rpy="0 0 0" xyz="0.025 0 0"/>
    <axis xyz="0 0 1"/>
    <dynamics damping="0.1" friction="0.1" />
  </joint> -->
  <link name="palm">
    <collision name="palm_collision">
      <geometry>
        <box size="0.05 0.25 0.05"/>
      </geometry>
      <origin rpy="0 0 0 " xyz="0.025 0 0"/>
    </collision>
    <visual name="visual">
      <geometry>
        <box size="0.05 0.25 0.05"/>
      </geometry>
      <origin rpy="0 0 0 " xyz="0.025 0 0"/>
    </visual>
    <inertial>
      <!-- <xacro:insert_block name="origin"/> -->
      <origin rpy="0 0 0" xyz="0.025 0 0"/>
      <mass value="0.8"/>
      <inertia ixx="0.004333333333333333" ixy="0.0" ixz="0.0" iyy="0.0003333333333333334" iyz="0.0" izz="0.004333333333333333"/>
    </inertial>
  </link>
  <joint name="palm_left_finger" type="prismatic">
    <child link="left_finger"/>
    <parent link="palm"/>
    <limit effort="1000.0" lower="0" upper="0.1" velocity="0.5"/>
    <origin rpy="0 0 0" xyz="0.125 0.025 0"/>
    <axis xyz="0 1 0"/>
    <dynamics damping="0" friction="0.1"/>
  </joint>
  <link name="left_finger">
    <collision name="left_finger_collision">
      <geometry>
        <box size="0.15 0.05 0.05"/>
      </geometry>
      <origin rpy="0 0 0 " xyz="0 0 0"/>
    </collision>
    <visual name="visual">
      <geometry>
        <box size="0.15 0.05 0.05"/>
      </geometry>
      <origin rpy="0 0 0 " xyz="0 0 0"/>
    </visual>
    <inertial>
      <!-- <xacro:insert_block name="origin"/> -->
      <origin rpy="0 0 0" xyz="0 0 0"/>
      <mass value="0.3"/>
      <inertia ixx="0.000125" ixy="0.0" ixz="0.0" iyy="0.000625" iyz="0.0" izz="0.000625"/>
    </inertial>
  </link>
  <joint name="palm_right_finger" type="prismatic">
    <child link="right_finger"/>
    <parent link="palm"/>
    <limit effort="1000.0" lower="0" upper="0.1" velocity="0.5"/>
    <origin rpy="0 0 0" xyz="0.125 -0.025 0"/>
    <axis xyz="0 -1 0"/>
    <dynamics damping="0" friction="0.1"/>
  </joint>
  <link name="right_finger">
    <collision name="right_finger_collision">
      <geometry>
        <box size="0.15 0.05 0.05"/>
      </geometry>
      <origin rpy="0 0 0 " xyz="0 0 0"/>
    </collision>
    <visual name="visual">
      <geometry>
        <box size="0.15 0.05 0.05"/>
      </geometry>
      <origin rpy="0 0 0 " xyz="0 0 0"/>
    </visual>
    <inertial>
      <!-- <xacro:insert_block name="origin"/> -->
      <origin rpy="0 0 0" xyz="0 0 0"/>
      <mass value="0.3"/>
      <inertia ixx="0.000125" ixy="0.0" ixz="0.0" iyy="0.000625" iyz="0.0" izz="0.000625"/>
    </inertial>
  </link>
  <joint name="left_wheel_hinge" type="continuous">
    <origin rpy="0 0 0" xyz="0.15 0.30 0"/>
    <parent link="chassis"/>
    <child link="left_wheel"/>
    <axis rpy="0 0 0" xyz="0 1 0"/>
    <limit effort="1000000" velocity="1000"/>
    <dynamics damping="1.0" friction="1.0"/>
  </joint>
  <link name="left_wheel">
    <inertial>
      <origin rpy="0 1.5707963267948966 1.5707963267948966" xyz="0 0 0"/>
      <mass value="2"/>
      <inertia ixx="0.005416666666666668" ixy="0.0" ixz="0.0" iyy="0.005416666666666668" iyz="0.0" izz="0.010000000000000002"/>
    </inertial>
    <collision>
      <origin rpy="0 1.5707 1.5707" xyz="0 0 0"/>
      <geometry>
        <cylinder length="0.05" radius="0.1"/>
      </geometry>
    </collision>
    <visual>
      <origin rpy="0 1.5707 1.5707" xyz="0 0 0"/>
      <geometry>
        <cylinder length="0.05" radius="0.1"/>
      </geometry>
    </visual>
  </link>
  <joint name="right_wheel_hinge" type="continuous">
    <origin rpy="0 0 0" xyz="0.15 -0.30 0"/>
    <parent link="chassis"/>
    <child link="right_wheel"/>
    <axis rpy="0 0 0" xyz="0 1 0"/>
    <limit effort="1000000" velocity="1000"/>
    <dynamics damping="1.0" friction="1.0"/>
  </joint>
  <link name="right_wheel">
    <inertial>
      <origin rpy="0 1.5707963267948966 1.5707963267948966" xyz="0 0 0"/>
      <mass value="2"/>
      <inertia ixx="0.005416666666666668" ixy="0.0" ixz="0.0" iyy="0.005416666666666668" iyz="0.0" izz="0.010000000000000002"/>
    </inertial>
    <collision>
      <origin rpy="0 1.5707 1.5707" xyz="0 0 0"/>
      <geometry>
        <cylinder length="0.05" radius="0.1"/>
      </geometry>
    </collision>
    <visual>
      <origin rpy="0 1.5707 1.5707" xyz="0 0 0"/>
      <geometry>
        <cylinder length="0.05" radius="0.1"/>
      </geometry>
    </visual>
  </link>
  <joint name="left_wheel_back_hinge" type="continuous">
    <origin rpy="0 0 0" xyz="-0.15 0.30 0"/>
    <parent link="chassis"/>
    <child link="left_wheel_back"/>
    <axis rpy="0 0 0" xyz="0 1 0"/>
    <limit effort="1000000" velocity="1000"/>
    <dynamics damping="1.0" friction="1.0"/>
  </joint>
  <link name="left_wheel_back">
    <inertial>
      <origin rpy="0 1.5707963267948966 1.5707963267948966" xyz="0 0 0"/>
      <mass value="2"/>
      <inertia ixx="0.005416666666666668" ixy="0.0" ixz="0.0" iyy="0.005416666666666668" iyz="0.0" izz="0.010000000000000002"/>
    </inertial>
    <collision>
      <origin rpy="0 1.5707 1.5707" xyz="0 0 0"/>
      <geometry>
        <cylinder length="0.05" radius="0.1"/>
      </geometry>
    </collision>
    <visual>
      <origin rpy="0 1.5707 1.5707" xyz="0 0 0"/>
      <geometry>
        <cylinder length="0.05" radius="0.1"/>
      </geometry>
    </visual>
  </link>
  <joint name="right_wheel_back_hinge" type="continuous">
    <origin rpy="0 0 0" xyz="-0.15 -0.30 0"/>
    <parent link="chassis"/>
    <child link="right_wheel_back"/>
    <axis rpy="0 0 0" xyz="0 1 0"/>
    <limit effort="1000000" velocity="1000"/>
    <dynamics damping="1.0" friction="1.0"/>
  </joint>
  <link name="right_wheel_back">
    <inertial>
      <origin rpy="0 1.5707963267948966 1.5707963267948966" xyz="0 0 0"/>
      <mass value="2"/>
      <inertia ixx="0.005416666666666668" ixy="0.0" ixz="0.0" iyy="0.005416666666666668" iyz="0.0" izz="0.010000000000000002"/>
    </inertial>
    <collision>
      <origin rpy="0 1.5707 1.5707" xyz="0 0 0"/>
      <geometry>
        <cylinder length="0.05" radius="0.1"/>
      </geometry>
    </collision>
    <visual>
      <origin rpy="0 1.5707 1.5707" xyz="0 0 0"/>
      <geometry>
        <cylinder length="0.05" radius="0.1"/>
      </geometry>
    </visual>
  </link>
  <joint name="camera_joint" type="fixed">
    <origin rpy="0 0 0" xyz="0.025 0 0.05"/>
    <parent link="palm"/>
    <child link="camera"/>
    <axis xyz="0 0 1"/>
  </joint>
  <link name="camera">
    <inertial>
      <!-- <xacro:insert_block name="origin"/> -->
      <origin rpy="0 0 0" xyz="0 0 0"/>
      <mass value="0.01"/>
      <inertia ixx="4.166666666666667e-06" ixy="0.0" ixz="0.0" iyy="4.166666666666667e-06" iyz="0.0" izz="4.166666666666667e-06"/>
    </inertial>
    <!-- <collision>
        <origin xyz="0 0 0" rpy="0 0 0"/>
        <geometry>
          <box size="0.05 0.05 0.05"/>
        </geometry>
      </collision> -->
    <visual>
      <origin rpy="0 0 0" xyz="0 0 0"/>
      <geometry>
        <box size="0.05 0.05 0.05"/>
      </geometry>
    </visual>
  </link>
  <joint name="camera_optical_joint" type="fixed">
    <parent link="camera"/>
    <child link="camera_optical"/>
    <origin rpy="-1.5707963267948966 0.0 -1.5707963267948966" xyz="0.0 0.0 0.0"/>
  </joint>
  <link name="camera_optical"/>
</robot>

